<?xml version="1.0"?>
<robot xmlns:xacro="http://ros.org/wiki/xacro" name="xarm_gripper">
<!--
  Author: Jason Peng <jason@ufactory.cc>
-->
  <xacro:macro name="xarm_gripper_urdf" params="prefix:='' attach_to:='' rpy:='0 0 0' xyz:='0 0 0' ">
  <xacro:unless value="${attach_to == ''}">
    <joint name="${prefix}gripper_fix" type="fixed">
      <parent link="${attach_to}"/>
      <child link="${prefix}xarm_gripper_base_link"/>
      <origin xyz="${xyz}" rpy="${rpy}"/>
    </joint>
  </xacro:unless>
  <link
    name="${prefix}xarm_gripper_base_link">
    <inertial>
      <origin
        xyz="-0.00065489 -0.0018497 0.048028"
        rpy="0 0 0" />
      <mass
        value="0.54156" />
      <inertia
        ixx="0.00047106"
        ixy="3.9292E-07"
        ixz="2.6537E-06"
        iyy="0.00033072"
        iyz="-1.0975E-05"
        izz="0.00025642" />
    </inertial>
    <visual>
      <origin
        xyz="0 0 0"
        rpy="0 0 0" />
      <geometry>
        <mesh
          filename="package://xarm_gripper/meshes/base_link.STL" />
      </geometry>
      <!-- <material
        name="">
        <color
          rgba="0.89804 0.91765 0.92941 1" />
      </material> -->
      <material name="White">
        <color rgba="1.0 1.0 1.0 1.0"/>
      </material>
    </visual>
    <collision>
      <origin
        xyz="-0.0015 0 0.0515"
        rpy="0 0 0" />
      <geometry>
        <box size="0.053 0.12 0.103"/>
      </geometry>
    </collision>
  </link>
  <link
    name="${prefix}left_outer_knuckle">
    <inertial>
      <origin
        xyz="2.9948E-14 0.021559 0.015181"
        rpy="0 0 0" />
      <mass
        value="0.1" />
      <inertia
        ixx="5.7284E-05"
        ixy="0"
        ixz="0"
        iyy="1.9708E-05"
        iyz="-2.1717E-05"
        izz="3.9220E-05" />
    </inertial>
    <visual>
      <origin
        xyz="0 0 0"
        rpy="0 0 0" />
      <geometry>
        <mesh
          filename="package://xarm_gripper/meshes/left_outer_knuckle.STL" />
      </geometry>
      <material name="Silver">
        <color rgba="0.753 0.753 0.753 1.0"/>
      </material>
    </visual>
    <collision>
      <origin
        xyz="0 0.015 0.02"
        rpy="0.48 0 0" />
      <geometry>
        <box size="0.012 0.069 0.033"/>
      </geometry>
    </collision>
    <collision>
      <geometry>
        <mesh
          scale="0.02 0.07 0.07"
          filename="package://xarm_gripper/meshes/simple_gear_for_gripper.stl" />
      </geometry>
    </collision>
  </link>
  <gazebo>
    <joint name="${prefix}left_loop_joint" type="revolute">
      <parent>${prefix}left_inner_knuckle</parent>
      <child>${prefix}left_finger</child>
      <pose>0 -0.015 0.015 0 0 0</pose>
      <axis>
        <xyz>1 0 0</xyz>
      </axis>
      <physics>
        <ode>
          <implicit_spring_damper>1</implicit_spring_damper>
        </ode>
      </physics>
    </joint>
  </gazebo>
  <joint
    name="${prefix}drive_joint"
    type="revolute">
    <origin
      xyz="0 0.035 0.059098"
      rpy="0 0 0" />
    <parent
      link="${prefix}xarm_gripper_base_link" />
    <child
      link="${prefix}left_outer_knuckle" />
    <axis
      xyz="1 0 0" />
    <limit
      lower="0"
      upper="0.85"
      effort="50"
      velocity="2" />
  </joint>
  <link
    name="${prefix}left_finger">
    <inertial>
      <origin
        xyz="-2.4536E-14 -0.016413 0.029258"
        rpy="0 0 0" />
      <mass
        value="0.1" />
      <inertia
        ixx="3.6214E-05"
        ixy="0"
        ixz="0"
        iyy="3.5660E-05"
        iyz="9.6127E-06"
        izz="1.0655E-05" />
    </inertial>
    <visual>
      <origin
        xyz="0 0 0"
        rpy="0 0 0" />
      <geometry>
        <mesh
          filename="package://xarm_gripper/meshes/left_finger.STL" />
      </geometry>
      <material name="Silver">
        <color rgba="0.753 0.753 0.753 1.0"/>
      </material>
    </visual>
    <collision>
      <origin
        xyz="0 -0.019 0.04"
        rpy="0 0 0" />
      <geometry>
        <box size="0.032 0.014 0.042"/>
      </geometry>
    </collision>
    <collision>
      <origin
        xyz="0 -0.008 0.008"
        rpy="0.8 0 0" />
      <geometry>
        <box size="0.016 0.012 0.036"/>
      </geometry>
    </collision>
  </link>
  <joint
    name="${prefix}left_finger_joint"
    type="revolute">
    <origin
      xyz="0 0.035465 0.042039"
      rpy="0 0 0" />
    <parent
      link="${prefix}left_outer_knuckle" />
    <child
      link="${prefix}left_finger" />
    <axis
      xyz="-1 0 0" />
    <limit
      lower="0"
      upper="0.85"
      effort="50"
      velocity="2" />
    <mimic joint="${prefix}drive_joint" multiplier="1" offset="0" />
  </joint>
  <link
    name="${prefix}left_inner_knuckle">
    <inertial>
      <origin
        xyz="1.86600784687907E-06 0.0220467847633621 0.0261334672830885"
        rpy="0 0 0" />
      <mass
        value="0.1" />
      <inertia
        ixx="2.6486E-05"
        ixy="0"
        ixz="0"
        iyy="2.6158E-05"
        iyz="-1.1864E-05"
        izz="2.2069E-05" />
    </inertial>
    <visual>
      <origin
        xyz="0 0 0"
        rpy="0 0 0" />
      <geometry>
        <mesh
          filename="package://xarm_gripper/meshes/left_inner_knuckle.STL" />
      </geometry>
      <material name="Silver">
        <color rgba="0.753 0.753 0.753 1.0"/>
      </material>
    </visual>
  </link>
  <joint
    name="${prefix}left_inner_knuckle_joint"
    type="revolute">
    <origin
      xyz="0 0.02 0.074098"
      rpy="0 0 0" />
    <parent
      link="${prefix}xarm_gripper_base_link" />
    <child
      link="${prefix}left_inner_knuckle" />
    <axis
      xyz="1 0 0" />
    <limit
      lower="0"
      upper="0.85"
      effort="50"
      velocity="2" />
    <mimic joint="${prefix}drive_joint" multiplier="1" offset="0" />
  </joint>
  <link
    name="${prefix}right_outer_knuckle">
    <inertial>
      <origin
        xyz="-3.1669E-14 -0.021559 0.015181"
        rpy="0 0 0" />
      <mass
        value="0.1" />
      <inertia
        ixx="5.7284E-05"
        ixy="0"
        ixz="0"
        iyy="1.9708E-05"
        iyz="2.1717E-05"
        izz="3.9220E-05" />
    </inertial>
    <visual>
      <origin
        xyz="0 0 0"
        rpy="0 0 0" />
      <geometry>
        <mesh
          filename="package://xarm_gripper/meshes/right_outer_knuckle.STL" />
      </geometry>
      <material name="Silver">
        <color rgba="0.753 0.753 0.753 1.0"/>
      </material>
    </visual>
    <collision>
      <origin
        xyz="0 -0.015 0.02"
        rpy="-0.48 0 0" />
      <geometry>
        <box size="0.012 0.069 0.033"/>
      </geometry>
    </collision>
    <collision>
      <geometry>
        <mesh
          scale="0.02 0.07 0.07"
          filename="package://xarm_gripper/meshes/simple_gear_for_gripper.stl" />
      </geometry>
    </collision>
  </link>

  <gazebo>
    <joint name="${prefix}right_loop_joint" type="revolute">
      <parent>${prefix}right_inner_knuckle</parent>
      <child>${prefix}right_finger</child>
      <pose>0 0.015 0.015 0 0 0</pose>
      <axis>
        <xyz>1 0 0</xyz>
      </axis>
      <physics>
        <ode>
          <implicit_spring_damper>1</implicit_spring_damper>
        </ode>
      </physics>
    </joint>
  </gazebo>
  <joint
    name="${prefix}right_outer_knuckle_joint"
    type="revolute">
    <origin
      xyz="0 -0.035 0.059098"
      rpy="0 0 0" />
    <parent
      link="${prefix}xarm_gripper_base_link" />
    <child
      link="${prefix}right_outer_knuckle" />
    <axis
      xyz="-1 0 0" />
    <limit
      lower="0"
      upper="0.85"
      effort="50"
      velocity="2" />
    <mimic joint="${prefix}drive_joint" multiplier="1" offset="0" />
  </joint>
  <link
    name="${prefix}right_finger">
    <inertial>
      <origin
        xyz="2.5618E-14 0.016413 0.029258"
        rpy="0 0 0" />
      <mass
        value="0.1" />
      <inertia
        ixx="3.6214E-05"
        ixy="0"
        ixz="0"
        iyy="3.5660E-05"
        iyz="-9.6127E-06"
        izz="1.0655E-05" />
    </inertial>
    <visual>
      <origin
        xyz="0 0 0"
        rpy="0 0 0" />
      <geometry>
        <mesh
          filename="package://xarm_gripper/meshes/right_finger.STL" />
      </geometry>
      <material name="Silver">
        <color rgba="0.753 0.753 0.753 1.0"/>
      </material>
    </visual>
    <collision>
      <origin
        xyz="0 0.019 0.04"
        rpy="0 0 0" />
      <geometry>
        <box size="0.032 0.014 0.042"/>
      </geometry>
    </collision>
    <collision>
      <origin
        xyz="0 0.008 0.008"
        rpy="-0.8 0 0" />
      <geometry>
        <box size="0.016 0.012 0.036"/>
      </geometry>
    </collision>
  </link>
  <joint
    name="${prefix}right_finger_joint"
    type="revolute">
    <origin
      xyz="0 -0.035465 0.042039"
      rpy="0 0 0" />
    <parent
      link="${prefix}right_outer_knuckle" />
    <child
      link="${prefix}right_finger" />
    <axis
      xyz="1 0 0" />
    <limit
      lower="0"
      upper="0.85"
      effort="50"
      velocity="2" />
    <mimic joint="${prefix}drive_joint" multiplier="1" offset="0" />
  </joint>
  <link
    name="${prefix}right_inner_knuckle">
    <inertial>
      <origin
        xyz="1.866E-06 -0.022047 0.026133"
        rpy="0 0 0" />
      <mass
        value="0.1" />
      <inertia
        ixx="2.6486E-05"
        ixy="0"
        ixz="0"
        iyy="2.6158E-05"
        iyz="1.1864E-05"
        izz="2.2069E-05" />
    </inertial>
    <visual>
      <origin
        xyz="0 0 0"
        rpy="0 0 0" />
      <geometry>
        <mesh
          filename="package://xarm_gripper/meshes/right_inner_knuckle.STL" />
      </geometry>
      <material name="Silver">
        <color rgba="0.753 0.753 0.753 1.0"/>
      </material>
    </visual>
  </link>
  <joint
    name="${prefix}right_inner_knuckle_joint"
    type="revolute">
    <origin
      xyz="0 -0.02 0.074098"
      rpy="0 0 0" />
    <parent
      link="${prefix}xarm_gripper_base_link" />
    <child
      link="${prefix}right_inner_knuckle" />
    <axis
      xyz="-1 0 0" />
    <limit
      lower="0"
      upper="0.85"
      effort="50"
      velocity="2" />
    <mimic joint="${prefix}drive_joint" multiplier="1" offset="0" />
  </joint>

  <link name="${prefix}link_tcp" />

  <joint
    name="${prefix}joint_tcp"
    type="fixed">
    <origin
      xyz="0 0 0.172"
      rpy="0 0 0" />
    <parent
      link="${prefix}xarm_gripper_base_link" />
    <child
      link="${prefix}link_tcp" />
  </joint>

  </xacro:macro>

</robot>